Workbook
Name _13MONTH: #REF!
Name _13MONTH: #REF!
Name exhibit1: #REF!
Name exhibit1: #REF!
Name exhibit12: #REF!
Name exhibit12: #REF!
Name exhibit3: #REF!
Name exhibit3: #REF!
Name exhibit4: #REF!
Name exhibit4: #REF!
Name exhibit5: #REF!
Name exhibit5: #REF!
Name EXPREAL: #REF!
Name EXPREAL: #REF!
Name gnsaexp: '[1]NSA Goods Exports'!$A$4:$S$300
Name gnsaexpcountries: '[1]NSA Goods Exports'!$A$4:$S$4
Name gnsaexpquarters: '[1]NSA Goods Exports'!$A$4:$A$500
Name gnsaimp: '[1]NSA Goods Imports'!$A$4:$S$500
Name gnsaimpcountries: '[1]NSA Goods Imports'!$A$4:$S$4
Name gnsaimpquarters: '[1]NSA Goods Imports'!$A$4:$A$500
Name gsaexp: '[1]SA Goods Exports Forced'!$A$4:$S$300
Name gsaexpcountries: '[1]SA Goods Exports Forced'!$A$4:$S$4
Name gsaexpquarters: '[1]SA Goods Exports Forced'!$A$4:$A$500
Name gsaimp: '[1]SA Goods Imports Forced'!$A$4:$S$500
Name gsaimpcountries: '[1]SA Goods Imports Forced'!$A$4:$S$4
Name gsaimpquarters: '[1]SA Goods Imports Forced'!$A$4:$A$500
Name gsfexp: '[1]SF Goods Exports'!$A$4:$S$500
Name gsfexpcountries: '[1]SF Goods Exports'!$A$4:$S$4
Name gsfexpquarters: '[1]SF Goods Exports'!$A$4:$A$500
Name gsfimp: '[1]SF Goods Imports'!$A$4:$S$500
Name gsfimpcountries: '[1]SF Goods Imports'!$A$4:$S$4
Name gsfimpquarters: '[1]SF Goods Imports'!$A$4:$A$500
Name IMPREAL: #REF!
Name IMPREAL: #REF!
Name PETROREAL: #REF!
Name PETROREAL: #REF!
Name PRINT: #REF!
Name PRINT: #REF!
Name qlookup: [1]Codes!$A$22:$B$25
Name snsaexp: '[1]NSA Services Exports'!$A$4:$S$500
Name snsaexpcountries: '[1]NSA Services Exports'!$A$4:$S$4
Name snsaexpquarters: '[1]NSA Services Exports'!$A$4:$A$500
Name snsaimp: '[1]NSA Services Imports'!$A$4:$S$500
Name snsaimpcountries: '[1]NSA Services Imports'!$A$4:$S$4
Name snsaimpquarters: '[1]NSA Services Imports'!$A$4:$A$500
Name ssaexp: '[1]SA Services Exports Forced'!$A$4:$S$500
Name ssaexpcountries: '[1]SA Services Exports Forced'!$A$4:$S$4
Name ssaexpquarters: '[1]SA Services Exports Forced'!$A$4:$A$500
Name ssaimp: '[1]SA Services Imports Forced'!$A$4:$S$500
Name ssaimpcountries: '[1]SA Services Imports Forced'!$A$4:$S$4
Name ssaimpquarters: '[1]SA Services Imports Forced'!$A$4:$A$500
Name ssfexp: '[1]SF Services Exports'!$A$4:$S$500
Name ssfexpcountries: '[1]SF Services Exports'!$A$4:$S$4
Name ssfexpquarters: '[1]SF Services Exports'!$A$4:$A$500
Name ssfimp: '[1]SF Services Imports'!$A$4:$S$500
Name ssfimpcountries: '[1]SF Services Imports'!$A$4:$S$4
Name ssfimpquarters: '[1]SF Services Imports'!$A$4:$A$500
Name SUP: #REF!
Name SUP: #REF!
Name TEST: #REF!

Sheet Exhibit 12A
A1: Part B: Not Seasonally Adjusted
A2: Imports of Goods by Principal End-Use Category
A3: In millions of dollars. Details may not equal totals due to seasonal adjustment and rounding.
A4: Period | B4: Total Census Basis (1) | C4: End-Use Commodity Category
C5: Foods, Feeds, Beverages | D5: Industrial Supplies (2) | E5: Capital Goods | F5: Automotive Vehicles, etc. | G5: Consumer Goods | H5: Other Goods
A6: 2025 | B6: 2321048 | C6: 150299 | D6: 509111 | E6: 722055 | F6: 288142 | G6: 553628 | H6: 97814 | I6: =G6/B6 -> 0.23852501
A7: January | B7: 317227 | C7: 20459 | D7: 88804 | E7: 83793 | F7: 35535 | G7: 77042 | H7: 11594 | I7: =G7/B7 -> 0.24286079
A8: February | B8: 288194 | C8: 17924 | D8: 76037 | E8: 77256 | F8: 34435 | G8: 71715 | H8: 10825 | I8: =G8/B8 -> 0.24884279
A9: March | B9: 342727 | C9: 20650 | D9: 73528 | E9: 93556 | F9: 43067 | G9: 99360 | H9: 12565 | I9: =G9/B9 -> 0.28991005
A10: April | B10: 276133 | C10: 19214 | D10: 53571 | E10: 89384 | F10: 34157 | G10: 67604 | H10: 12205 | I10: =G10/B10 -> 0.24482405
A11: May | B11: 276403 | C11: 19105 | D11: 52848 | E11: 91029 | F11: 36882 | G11: 63867 | H11: 12672 | I11: =G11/B11 -> 0.23106479
A12: June | B12: 265518 | C12: 18249 | D12: 49925 | E12: 94164 | F12: 34930 | G12: 56099 | H12: 12152 | I12: =G12/B12 -> 0.21128134
A13: July | B13: 292215 | C13: 18526 | D13: 64249 | E13: 100561 | F13: 34098 | G13: 61612 | H13: 13170 | I13: =G13/B13 -> 0.21084475
A14: August | B14: 262632 | C14: 16173 | D14: 50149 | E14: 92311 | F14: 35038 | G14: 56329 | H14: 12632 | I14: =G14/B14 -> 0.21447881
A15: September | I15: =G15/B15 -> #VALUE!
A16: October | I16: =G16/B16 -> #VALUE!
A17: November | I17: =G17/B17 -> #VALUE!
A18: December | I18: =G18/B18 -> #VALUE!
A19: 2024 | B19: 3266410 | C19: 216021 | D19: 675771 | E19: 961759 | F19: 474380 | G19: 805674 | H19: 132805 | I19: =G19/B19 -> 0.24665428
A20: January | B20: 253693 | C20: 17382 | D20: 54906 | E20: 71408 | F20: 37763 | G20: 62063 | H20: 10171 | I20: =G20/B20 -> 0.2446382
A21: February | B21: 242229 | C21: 17121 | D21: 49747 | E21: 68114 | F21: 38144 | G21: 58876 | H21: 10227 | I21: =G21/B21 -> 0.24305925
A22: March | B22: 259087 | C22: 18431 | D22: 53140 | E22: 76108 | F22: 39626 | G22: 60936 | H22: 10846 | I22: =G22/B22 -> 0.23519513
A23: April | B23: 270974 | C23: 18352 | D23: 57063 | E23: 77168 | F23: 42297 | G23: 64641 | H23: 11453 | I23: =G23/B23 -> 0.23855056
A24: May | B24: 274906 | C24: 18483 | D24: 60071 | E24: 79657 | F24: 41094 | G24: 64042 | H24: 11560 | I24: =G24/B24 -> 0.23295963
A25: June | B25: 266057 | C25: 17090 | D25: 56165 | E25: 80470 | F25: 39353 | G25: 62093 | H25: 10887 | I25: =G25/B25 -> 0.23338232
A26: July | B26: 288127 | C26: 17813 | D26: 62050 | E26: 86559 | F26: 40114 | G26: 70501 | H26: 11090 | I26: =G26/B26 -> 0.24468724
A27: August | B27: 277306 | C27: 17558 | D27: 55609 | E27: 83886 | F27: 39903 | G27: 69642 | H27: 10708 | I27: =G27/B27 -> 0.25113773
A28: September | B28: 285963 | C28: 17622 | D28: 55027 | E28: 86974 | F28: 38818 | G28: 76059 | H28: 11463 | I28: =G28/B28 -> 0.26597497
A29: October | B29: 288844 | C29: 18690 | D29: 54386 | E29: 84689 | F29: 40469 | G29: 78751 | H29: 11859 | I29: =G29/B29 -> 0.27264198
A30: November | B30: 274312 | C30: 18674 | D30: 53701 | E30: 81920 | F30: 39267 | G30: 69393 | H30: 11357 | I30: =G30/B30 -> 0.25297107
A31: December | B31: 284911 | C31: 18803 | D31: 63907 | E31: 84808 | F31: 37532 | G31: 68678 | H31: 11182 | I31: =G31/B31 -> 0.24105071
A32: 2023 | B32: 3076796 | C32: 200201 | D32: 674604 | E32: 858326 | F32: 456963 | G32: 757239 | H32: 129462 | I32: =G32/B32 -> 0.24611284
A33: January | B33: 254626 | C33: 17559 | D33: 60093 | E33: 68165 | F33: 34367 | G33: 64737 | H33: 9705 | I33: =G33/B33 -> 0.25424348
A34: February | B34: 230170 | C34: 15466 | D34: 52699 | E34: 63370 | F34: 32653 | G34: 55885 | H34: 10098 | I34: =G34/B34 -> 0.2427988
A35: March | B35: 261244 | C35: 18051 | D35: 57909 | E35: 73898 | F35: 38045 | G35: 61552 | H35: 11790 | I35: =G35/B35 -> 0.23561115
A36: April | B36: 249869 | C36: 16530 | D36: 59175 | E36: 68239 | F36: 36643 | G36: 58943 | H36: 10339 | I36: =G36/B36 -> 0.23589561
A37: May | B37: 263245 | C37: 17368 | D37: 60332 | E37: 73828 | F37: 38034 | G37: 62299 | H37: 11384 | I37: =G37/B37 -> 0.23665787
A38: June | B38: 257211 | C38: 16731 | D38: 56406 | E38: 73053 | F38: 38793 | G38: 61342 | H38: 10886 | I38: =G38/B38 -> 0.23848902
A39: July | B39: 255333 | C39: 16643 | D39: 54472 | E39: 71650 | F39: 38209 | G39: 63792 | H39: 10567 | I39: =G39/B39 -> 0.24983845
A40: August | B40: 265555 | C40: 16763 | D40: 58331 | E40: 72844 | F40: 40181 | G40: 66951 | H40: 10486 | I40: =G40/B40 -> 0.25211726
...

Sheet Sheet1
A1: Year | B1: share_imports_consumption
A2: 1992 | B2: 0.23027006
A3: 1993 | B3: ='Exhibit 12A'!I422 -> 0.23079467
A4: 1994 | B4: ='Exhibit 12A'!I409 -> 0.22053928
A5: 1995 | B5: ='Exhibit 12A'!I396 -> 0.21505817
A6: 1996 | B6: ='Exhibit 12A'!I383 -> 0.21625221
A7: 1997 | B7: ='Exhibit 12A'!I370 -> 0.22284708
A8: 1998 | B8: ='Exhibit 12A'!I357 -> 0.23796135
A9: 1999 | B9: ='Exhibit 12A'!I344 -> 0.23609287
A10: 2000 | B10: ='Exhibit 12A'!I331 -> 0.23138498
A11: 2001 | B11: ='Exhibit 12A'!I318 -> 0.24916148
A12: 2002 | B12: ='Exhibit 12A'!I305 -> 0.26506889
A13: 2003 | B13: ='Exhibit 12A'!I292 -> 0.26558939
A14: 2004 | B14: ='Exhibit 12A'!I279 -> 0.25375042
A15: 2005 | B15: ='Exhibit 12A'!I266 -> 0.24335103
A16: 2006 | B16: ='Exhibit 12A'!I253 -> 0.2387561
A17: 2007 | B17: ='Exhibit 12A'!I240 -> 0.24249423
A18: 2008 | B18: ='Exhibit 12A'!I227 -> 0.22895684
A19: 2009 | B19: ='Exhibit 12A'!I214 -> 0.27399663
A20: 2010 | B20: ='Exhibit 12A'!I201 -> 0.25248752
A21: 2011 | B21: ='Exhibit 12A'!I188 -> 0.23284362
A22: 2012 | B22: ='Exhibit 12A'!I175 -> 0.22709023
A23: 2013 | B23: ='Exhibit 12A'!I162 -> 0.23442551
A24: 2014 | B24: ='Exhibit 12A'!I149 -> 0.23641801
A25: 2015 | B25: ='Exhibit 12A'!I136 -> 0.26421918
A26: 2016 | B26: ='Exhibit 12A'!I123 -> 0.26664703
A27: 2017 | B27: ='Exhibit 12A'!I110 -> 0.25706117
A28: 2018 | B28: ='Exhibit 12A'!I97 -> 0.25446771
A29: 2019 | B29: ='Exhibit 12A'!I84 -> 0.26206887
A30: 2020 | B30: ='Exhibit 12A'!I71 -> 0.2743231
A31: 2021 | B31: ='Exhibit 12A'!I58 -> 0.27126142
A32: 2022 | B32: ='Exhibit 12A'!I45 -> 0.25870743
A33: 2023 | B33: ='Exhibit 12A'!I32 -> 0.24611284
A34: 2024 | B34: ='Exhibit 12A'!I19 -> 0.24665428
A35: 2025 | B35: ='Exhibit 12A'!I6 -> 0.23852501
